<?xml version="1.0" ?>

<sdf version='1.6'>
  <world name='default'>
    <model name='ground_plane'>
      <static>1</static>
      <link name='link'>
        <collision name='collision'>
          <geometry>
            <plane>
              <normal>0 0 1</normal>
              <size>100 100</size>
            </plane>
          </geometry>
          <surface>
            <contact>
              <collide_bitmask>65535</collide_bitmask>
              <ode/>
            </contact>
            <friction>
              <ode>
                <mu>100</mu>
                <mu2>50</mu2>
              </ode>
              <torsional>
                <ode/>
              </torsional>
            </friction>
            <bounce/>
          </surface>
          <max_contacts>10</max_contacts>
        </collision>
        <visual name='visual'>
          <cast_shadows>0</cast_shadows>
          <geometry>
            <plane>
              <normal>0 0 1</normal>
              <size>100 100</size>
            </plane>
          </geometry>
          <material>
            <script>
              <uri>file://media/materials/scripts/gazebo.material</uri>
              <name>Gazebo/Grey</name>
            </script>
          </material>
        </visual>
        <self_collide>0</self_collide>
        <enable_wind>0</enable_wind>
        <kinematic>0</kinematic>
      </link>
    </model>
    <light name='sun' type='directional'>
      <cast_shadows>1</cast_shadows>
      <pose frame=''>0 0 10 0 -0 0</pose>
      <diffuse>0.8 0.8 0.8 1</diffuse>
      <specular>0.2 0.2 0.2 1</specular>
      <attenuation>
        <range>1000</range>
        <constant>0.9</constant>
        <linear>0.01</linear>
        <quadratic>0.001</quadratic>
      </attenuation>
      <direction>-0.5 0.1 -0.9</direction>
    </light>
    <physics name='default_physics' default='0' type='ode'>
      <max_step_size>0.001</max_step_size>
      <real_time_factor>1</real_time_factor>
      <real_time_update_rate>1000</real_time_update_rate>
    </physics>
    <gui fullscreen='0'>
      <camera name='user_camera'>
        <pose frame=''>6.89955 -4.60267 3.3703 0 0.275643 2.35619</pose>
        <view_controller>orbit</view_controller>
        <projection_type>perspective</projection_type>
      </camera>
    </gui>
    <gravity>0 0 -9.8</gravity>
    <magnetic_field>6e-06 2.3e-05 -4.2e-05</magnetic_field>
    <atmosphere type='adiabatic'/>
    <scene>
      <ambient>0.4 0.4 0.4 1</ambient>
      <background>0.7 0.7 0.7 1</background>
      <shadows>1</shadows>
    </scene>
    <audio>
      <device>default</device>
    </audio>
    <wind/>
    <spherical_coordinates>
      <surface_model>EARTH_WGS84</surface_model>
      <latitude_deg>0</latitude_deg>
      <longitude_deg>0</longitude_deg>
      <elevation>0</elevation>
      <heading_deg>0</heading_deg>
    </spherical_coordinates>
    <model name='kuka_kr6r900sixx'>
      <link name='table'>
        <pose frame=''>0.6 0 0.2 0 -0 0</pose>
        <inertial>
          <pose frame=''>-0.092308 0 0.046154 0 -0 0</pose>
          <mass>130</mass>
          <inertia>
            <ixx>3.68708</ixx>
            <ixy>0</ixy>
            <ixz>1.84615</ixz>
            <iyy>14.4574</iyy>
            <iyz>0</iyz>
            <izz>13.5563</izz>
          </inertia>
        </inertial>
        <collision name='table_collision'>
          <pose frame=''>0 0 0 0 -0 0</pose>
          <geometry>
            <box>
              <size>1.2 0.8 0.4</size>
            </box>
          </geometry>
          <max_contacts>10</max_contacts>
          <surface>
            <contact>
              <ode/>
            </contact>
            <bounce/>
            <friction>
              <torsional>
                <ode/>
              </torsional>
              <ode/>
            </friction>
          </surface>
        </collision>
        <collision name='table_fixed_joint_lump__base_link_collision_1'>
          <pose frame=''>-0.4 0 0.2 0 -0 0</pose>
          <geometry>
            <mesh>
              <scale>1 1 1</scale>
              <uri>/home/tomas/catkin_ws/src/ROS_KUKA_env/kuka_experimental/kuka_kr6_support/meshes/kr6_agilus/collision/base_link.stl</uri>
            </mesh>
          </geometry>
          <max_contacts>10</max_contacts>
          <surface>
            <contact>
              <ode/>
            </contact>
            <bounce/>
            <friction>
              <torsional>
                <ode/>
              </torsional>
              <ode/>
            </friction>
          </surface>
        </collision>
        <visual name='table_visual'>
          <pose frame=''>0 0 0 0 -0 0</pose>
          <geometry>
            <box>
              <size>1.2 0.8 0.4</size>
            </box>
          </geometry>
        </visual>
        <visual name='table_fixed_joint_lump__base_link_visual_1'>
          <pose frame=''>-0.4 0 0.2 0 -0 0</pose>
          <geometry>
            <mesh>
              <scale>1 1 1</scale>
              <uri>/home/tomas/catkin_ws/src/ROS_KUKA_env/kuka_experimental/kuka_kr6_support/meshes/kr6_agilus/visual/base_link.dae</uri>
            </mesh>
          </geometry>
        </visual>
        <self_collide>0</self_collide>
        <enable_wind>0</enable_wind>
        <kinematic>0</kinematic>
      </link>
      <joint name='joint_table' type='fixed'>
        <child>table</child>
        <parent>world</parent>
      </joint>
      <link name='link_1'>
        <pose frame=''>0.2 0 0.8 0 -0 0</pose>
        <inertial>
          <pose frame=''>0 0 0 0 -0 0</pose>
          <mass>12.5</mass>
          <inertia>
            <ixx>0.141</ixx>
            <ixy>0</ixy>
            <ixz>0</ixz>
            <iyy>0.121</iyy>
            <iyz>0</iyz>
            <izz>0.121</izz>
          </inertia>
        </inertial>
        <collision name='link_1_collision'>
          <pose frame=''>0 0 0 0 -0 0</pose>
          <geometry>
            <mesh>
              <scale>1 1 1</scale>
              <uri>/home/tomas/catkin_ws/src/ROS_KUKA_env/kuka_experimental/kuka_kr6_support/meshes/kr6_agilus/collision/link_1.stl</uri>
            </mesh>
          </geometry>
          <max_contacts>10</max_contacts>
          <surface>
            <contact>
              <ode/>
            </contact>
            <bounce/>
            <friction>
              <torsional>
                <ode/>
              </torsional>
              <ode/>
            </friction>
          </surface>
        </collision>
        <visual name='link_1_visual'>
          <pose frame=''>0 0 0 0 -0 0</pose>
          <geometry>
            <mesh>
              <scale>1 1 1</scale>
              <uri>/home/tomas/catkin_ws/src/ROS_KUKA_env/kuka_experimental/kuka_kr6_support/meshes/kr6_agilus/visual/link_1.dae</uri>
            </mesh>
          </geometry>
        </visual>
        <self_collide>0</self_collide>
        <enable_wind>0</enable_wind>
        <kinematic>0</kinematic>
      </link>
      <joint name='joint_a1' type='revolute'>
        <child>link_1</child>
        <parent>table</parent>
        <axis>
          <xyz>0 0 -1</xyz>
          <limit>
            <lower>-1.0472</lower>
            <upper>1.0472</upper>
            <effort>100</effort>
            <velocity>6.28319</velocity>
          </limit>
          <dynamics>
            <damping>0.7</damping>
            <friction>100</friction>
            <spring_reference>0</spring_reference>
            <spring_stiffness>0</spring_stiffness>
          </dynamics>
          <use_parent_model_frame>1</use_parent_model_frame>
        </axis>
      </joint>
      <link name='link_2'>
        <pose frame=''>0.225 0 0.8 0 -0 0</pose>
        <inertial>
          <pose frame=''>0 0 0 0 -0 0</pose>
          <mass>5</mass>
          <inertia>
            <ixx>0.072</ixx>
            <ixy>0</ixy>
            <ixz>0</ixz>
            <iyy>0.357</iyy>
            <iyz>0</iyz>
            <izz>0.345</izz>
          </inertia>
        </inertial>
        <collision name='link_2_collision'>
          <pose frame=''>0 0 0 0 -0 0</pose>
          <geometry>
            <mesh>
              <scale>1 1 1</scale>
              <uri>/home/tomas/catkin_ws/src/ROS_KUKA_env/kuka_experimental/kuka_kr6_support/meshes/kr6r900sixx/collision/link_2.stl</uri>
            </mesh>
          </geometry>
          <max_contacts>10</max_contacts>
          <surface>
            <contact>
              <ode/>
            </contact>
            <bounce/>
            <friction>
              <torsional>
                <ode/>
              </torsional>
              <ode/>
            </friction>
          </surface>
        </collision>
        <visual name='link_2_visual'>
          <pose frame=''>0 0 0 0 -0 0</pose>
          <geometry>
            <mesh>
              <scale>1 1 1</scale>
              <uri>/home/tomas/catkin_ws/src/ROS_KUKA_env/kuka_experimental/kuka_kr6_support/meshes/kr6r900sixx/visual/link_2.dae</uri>
            </mesh>
          </geometry>
        </visual>
        <self_collide>0</self_collide>
        <enable_wind>0</enable_wind>
        <kinematic>0</kinematic>
      </link>
      <joint name='joint_a2' type='revolute'>
        <child>link_2</child>
        <parent>link_1</parent>
        <axis>
          <xyz>0 1 0</xyz>
          <limit>
            <lower>-1.5708</lower>
            <upper>0.174533</upper>
            <effort>100</effort>
            <velocity>5.23599</velocity>
          </limit>
          <dynamics>
            <damping>0.7</damping>
            <friction>100</friction>
            <spring_reference>0</spring_reference>
            <spring_stiffness>0</spring_stiffness>
          </dynamics>
          <use_parent_model_frame>1</use_parent_model_frame>
        </axis>
      </joint>
      <link name='link_3'>
        <pose frame=''>0.68 0 0.8 0 -0 0</pose>
        <inertial>
          <pose frame=''>0 0 0 0 -0 0</pose>
          <mass>5</mass>
          <inertia>
            <ixx>0.011</ixx>
            <ixy>0</ixy>
            <ixz>0</ixz>
            <iyy>0.017</iyy>
            <iyz>0</iyz>
            <izz>0.018</izz>
          </inertia>
        </inertial>
        <collision name='link_3_collision'>
          <pose frame=''>0 0 0 0 -0 0</pose>
          <geometry>
            <mesh>
              <scale>1 1 1</scale>
              <uri>/home/tomas/catkin_ws/src/ROS_KUKA_env/kuka_experimental/kuka_kr6_support/meshes/kr6_agilus/collision/link_3.stl</uri>
            </mesh>
          </geometry>
          <max_contacts>10</max_contacts>
          <surface>
            <contact>
              <ode/>
            </contact>
            <bounce/>
            <friction>
              <torsional>
                <ode/>
              </torsional>
              <ode/>
            </friction>
          </surface>
        </collision>
        <visual name='link_3_visual'>
          <pose frame=''>0 0 0 0 -0 0</pose>
          <geometry>
            <mesh>
              <scale>1 1 1</scale>
              <uri>/home/tomas/catkin_ws/src/ROS_KUKA_env/kuka_experimental/kuka_kr6_support/meshes/kr6_agilus/visual/link_3.dae</uri>
            </mesh>
          </geometry>
        </visual>
        <self_collide>0</self_collide>
        <enable_wind>0</enable_wind>
        <kinematic>0</kinematic>
      </link>
      <joint name='joint_a3' type='revolute'>
        <child>link_3</child>
        <parent>link_2</parent>
        <axis>
          <xyz>0 1 0</xyz>
          <limit>
            <lower>0</lower>
            <upper>2.35619</upper>
            <effort>100</effort>
            <velocity>6.28319</velocity>
          </limit>
          <dynamics>
            <damping>0.7</damping>
            <friction>100</friction>
            <spring_reference>0</spring_reference>
            <spring_stiffness>0</spring_stiffness>
          </dynamics>
          <use_parent_model_frame>1</use_parent_model_frame>
        </axis>
      </joint>
      <link name='link_4'>
        <pose frame=''>0.68 0 0.835 0 -0 0</pose>
        <inertial>
          <pose frame=''>0 0 0 0 -0 0</pose>
          <mass>5</mass>
          <inertia>
            <ixx>0.01</ixx>
            <ixy>0</ixy>
            <ixz>0</ixz>
            <iyy>0.056</iyy>
            <iyz>0</iyz>
            <izz>0.056</izz>
          </inertia>
        </inertial>
        <collision name='link_4_collision'>
          <pose frame=''>0 0 0 0 -0 0</pose>
          <geometry>
            <mesh>
              <scale>1 1 1</scale>
              <uri>/home/tomas/catkin_ws/src/ROS_KUKA_env/kuka_experimental/kuka_kr6_support/meshes/kr6r900sixx/collision/link_4.stl</uri>
            </mesh>
          </geometry>
          <max_contacts>10</max_contacts>
          <surface>
            <contact>
              <ode/>
            </contact>
            <bounce/>
            <friction>
              <torsional>
                <ode/>
              </torsional>
              <ode/>
            </friction>
          </surface>
        </collision>
        <visual name='link_4_visual'>
          <pose frame=''>0 0 0 0 -0 0</pose>
          <geometry>
            <mesh>
              <scale>1 1 1</scale>
              <uri>/home/tomas/catkin_ws/src/ROS_KUKA_env/kuka_experimental/kuka_kr6_support/meshes/kr6r900sixx/visual/link_4.dae</uri>
            </mesh>
          </geometry>
        </visual>
        <self_collide>0</self_collide>
        <enable_wind>0</enable_wind>
        <kinematic>0</kinematic>
      </link>
      <joint name='joint_a4' type='revolute'>
        <child>link_4</child>
        <parent>link_3</parent>
        <axis>
          <xyz>-1 0 0</xyz>
          <limit>
            <lower>-1.5708</lower>
            <upper>1.5708</upper>
            <effort>100</effort>
            <velocity>6.6497</velocity>
          </limit>
          <dynamics>
            <damping>0.7</damping>
            <friction>100</friction>
            <spring_reference>0</spring_reference>
            <spring_stiffness>0</spring_stiffness>
          </dynamics>
          <use_parent_model_frame>1</use_parent_model_frame>
        </axis>
      </joint>
      <link name='link_5'>
        <pose frame=''>1.1 0 0.835 0 -0 0</pose>
        <inertial>
          <pose frame=''>0 0 0 0 -0 0</pose>
          <mass>2</mass>
          <inertia>
            <ixx>0.001</ixx>
            <ixy>0</ixy>
            <ixz>0</ixz>
            <iyy>0.01</iyy>
            <iyz>0</iyz>
            <izz>0.001</izz>
          </inertia>
        </inertial>
        <collision name='link_5_collision'>
          <pose frame=''>0 0 0 0 -0 0</pose>
          <geometry>
            <mesh>
              <scale>1 1 1</scale>
              <uri>/home/tomas/catkin_ws/src/ROS_KUKA_env/kuka_experimental/kuka_kr6_support/meshes/kr6_agilus/collision/link_5.stl</uri>
            </mesh>
          </geometry>
          <max_contacts>10</max_contacts>
          <surface>
            <contact>
              <ode/>
            </contact>
            <bounce/>
            <friction>
              <torsional>
                <ode/>
              </torsional>
              <ode/>
            </friction>
          </surface>
        </collision>
        <visual name='link_5_visual'>
          <pose frame=''>0 0 0 0 -0 0</pose>
          <geometry>
            <mesh>
              <scale>1 1 1</scale>
              <uri>/home/tomas/catkin_ws/src/ROS_KUKA_env/kuka_experimental/kuka_kr6_support/meshes/kr6_agilus/visual/link_5.dae</uri>
            </mesh>
          </geometry>
        </visual>
        <self_collide>0</self_collide>
        <enable_wind>0</enable_wind>
        <kinematic>0</kinematic>
      </link>
      <joint name='joint_a5' type='revolute'>
        <child>link_5</child>
        <parent>link_4</parent>
        <axis>
          <xyz>0 1 0</xyz>
          <limit>
            <lower>-1.5708</lower>
            <upper>1.91986</upper>
            <effort>100</effort>
            <velocity>6.77188</velocity>
          </limit>
          <dynamics>
            <damping>0.7</damping>
            <friction>100</friction>
            <spring_reference>0</spring_reference>
            <spring_stiffness>0</spring_stiffness>
          </dynamics>
          <use_parent_model_frame>1</use_parent_model_frame>
        </axis>
      </joint>
      <link name='link_6'>
        <pose frame=''>1.18 0 0.835 0 -0 0</pose>
        <inertial>
          <pose frame=''>0.003182 0 0 0 -0 0</pose>
          <mass>2.2</mass>
          <inertia>
            <ixx>0.00300002</ixx>
            <ixy>1.43339e-05</ixy>
            <ixz>0</ixz>
            <iyy>0.0302227</iyy>
            <iyz>0</iyz>
            <izz>0.00322273</izz>
          </inertia>
        </inertial>
        <collision name='link_6_collision'>
          <pose frame=''>0 0 0 0 -0 0</pose>
          <geometry>
            <mesh>
              <scale>1 1 1</scale>
              <uri>/home/tomas/catkin_ws/src/ROS_KUKA_env/kuka_experimental/kuka_kr6_support/meshes/kr6_agilus/collision/link_6.stl</uri>
            </mesh>
          </geometry>
          <max_contacts>10</max_contacts>
          <surface>
            <contact>
              <ode/>
            </contact>
            <bounce/>
            <friction>
              <torsional>
                <ode/>
              </torsional>
              <ode/>
            </friction>
          </surface>
        </collision>
        <collision name='link_6_fixed_joint_lump__tool0_collision_1'>
          <pose frame=''>0 0 0 0 -0 0</pose>
          <geometry>
            <mesh>
              <scale>0.001 0.001 0.001</scale>
              <uri>/home/tomas/catkin_ws/src/ROS_KUKA_env/kuka_experimental/kuka_kr6_support/meshes/kr6r900sixx/visual/priruba.stl</uri>
            </mesh>
          </geometry>
          <surface>
            <contact>
              <ode/>
            </contact>
            <friction>
              <ode/>
              <torsional>
                <ode/>
              </torsional>
            </friction>
            <bounce/>
          </surface>
          <max_contacts>10</max_contacts>
        </collision>
        <collision name='link_6_fixed_joint_lump__fingers_collision_2'>
          <pose frame=''>0.035 0 0 0 -0 3.14</pose>
          <geometry>
            <box>
              <size>0.07 0.02 0.02</size>
            </box>
          </geometry>
          <surface>
            <contact>
              <ode/>
            </contact>
            <friction>
              <ode/>
              <torsional>
                <ode/>
              </torsional>
            </friction>
            <bounce/>
          </surface>
          <max_contacts>10</max_contacts>
        </collision>
        <visual name='link_6_visual'>
          <pose frame=''>0 0 0 0 -0 0</pose>
          <geometry>
            <mesh>
              <scale>1 1 1</scale>
              <uri>/home/tomas/catkin_ws/src/ROS_KUKA_env/kuka_experimental/kuka_kr6_support/meshes/kr6_agilus/visual/link_6.dae</uri>
            </mesh>
          </geometry>
        </visual>
        <visual name='link_6_fixed_joint_lump__tool0_visual_1'>
          <pose frame=''>0 0 0 0 -0 0</pose>
          <geometry>
            <mesh>
              <scale>0.001 0.001 0.001</scale>
              <uri>/home/tomas/catkin_ws/src/ROS_KUKA_env/kuka_experimental/kuka_kr6_support/meshes/kr6r900sixx/visual/priruba.stl</uri>
            </mesh>
          </geometry>
          <material>
            <script>
              <name>Gazebo/Grey</name>
              <uri>file://media/materials/scripts/gazebo.material</uri>
            </script>
          </material>
        </visual>
        <visual name='link_6_fixed_joint_lump__fingers_visual_2'>
          <pose frame=''>0.035 0 0 0 -0 3.14</pose>
          <geometry>
            <box>
              <size>0.07 0.02 0.02</size>
            </box>
          </geometry>
          <material>
            <script>
              <name>Gazebo/Grey</name>
              <uri>file://media/materials/scripts/gazebo.material</uri>
            </script>
          </material>
        </visual>
        <velocity_decay/>
        <gravity>1</gravity>
        <velocity_decay/>
        <self_collide>0</self_collide>
        <enable_wind>0</enable_wind>
        <kinematic>0</kinematic>
      </link>
      <joint name='joint_a6' type='revolute'>
        <child>link_6</child>
        <parent>link_5</parent>
        <axis>
          <xyz>-1 0 0</xyz>
          <limit>
            <lower>-3.83972</lower>
            <upper>3.83972</upper>
            <effort>100</effort>
            <velocity>10.7338</velocity>
          </limit>
          <dynamics>
            <damping>0.7</damping>
            <friction>100</friction>
            <spring_reference>0</spring_reference>
            <spring_stiffness>0</spring_stiffness>
          </dynamics>
          <use_parent_model_frame>1</use_parent_model_frame>
        </axis>
      </joint>
      <static>0</static>
      <plugin name='gazebo_ros_control' filename='libgazebo_ros_control.so'>
        <robotNamespace>/</robotNamespace>
      </plugin>
      <pose frame=''>0 0 0 0 -0 0</pose>
    </model>
    <model name='unit_box'>
      <link name='link'>
        <inertial>
          <mass>1</mass>
          <inertia>
            <ixx>0.166667</ixx>
            <ixy>0</ixy>
            <ixz>0</ixz>
            <iyy>0.166667</iyy>
            <iyz>0</iyz>
            <izz>0.166667</izz>
          </inertia>
          <pose frame=''>0 0 0 0 -0 0</pose>
        </inertial>
        <self_collide>0</self_collide>
        <enable_wind>0</enable_wind>
        <kinematic>0</kinematic>
        <pose frame=''>0 0 0 0 -0 0</pose>
        <gravity>1</gravity>
        <visual name='visual'>
          <geometry>
            <box>
              <size>0.04 0.04 0.04</size>
            </box>
          </geometry>
          <material>
            <script>
              <name>Gazebo/Grey</name>
              <uri>file://media/materials/scripts/gazebo.material</uri>
            </script>
            <shader type='vertex'>
              <normal_map>__default__</normal_map>
            </shader>
            <ambient>0.3 0.3 0.7 1</ambient>
            <diffuse>0.7 0.7 0.7 1</diffuse>
            <specular>0.01 0.01 0.7 1</specular>
            <emissive>0 0 0 1</emissive>
          </material>
          <pose frame=''>0 0 0 0 -0 0</pose>
          <transparency>0</transparency>
          <cast_shadows>1</cast_shadows>
        </visual>
        <collision name='collision'>
          <laser_retro>0</laser_retro>
          <max_contacts>10</max_contacts>
          <pose frame=''>0 0 0 0 -0 0</pose>
          <geometry>
            <box>
              <size>0.04 0.04 0.04</size>
            </box>
          </geometry>
          <surface>
            <friction>
              <ode>
                <mu>1</mu>
                <mu2>1</mu2>
                <fdir1>0 0 0</fdir1>
                <slip1>0</slip1>
                <slip2>0</slip2>
              </ode>
              <torsional>
                <coefficient>1</coefficient>
                <patch_radius>0</patch_radius>
                <surface_radius>0</surface_radius>
                <use_patch_radius>1</use_patch_radius>
                <ode>
                  <slip>0</slip>
                </ode>
              </torsional>
            </friction>
            <bounce>
              <restitution_coefficient>0</restitution_coefficient>
              <threshold>1e+06</threshold>
            </bounce>
            <contact>
              <collide_without_contact>0</collide_without_contact>
              <collide_without_contact_bitmask>1</collide_without_contact_bitmask>
              <collide_bitmask>1</collide_bitmask>
              <ode>
                <soft_cfm>0</soft_cfm>
                <soft_erp>0.2</soft_erp>
                <kp>1e+13</kp>
                <kd>1</kd>
                <max_vel>0.01</max_vel>
                <min_depth>0</min_depth>
              </ode>
              <bullet>
                <split_impulse>1</split_impulse>
                <split_impulse_penetration_threshold>-0.01</split_impulse_penetration_threshold>
                <soft_cfm>0</soft_cfm>
                <soft_erp>0.2</soft_erp>
                <kp>1e+13</kp>
                <kd>1</kd>
              </bullet>
            </contact>
          </surface>
        </collision>
      </link>
      <static>0</static>
      <allow_auto_disable>1</allow_auto_disable>
      <plugin name='pushobject_plugin' filename='libpushobject_plugin.so'/>
      <pose frame=''>1.08452 0.735173 0 0 -0 0</pose>
    </model>
    <model name='goal'>
      <link name='link'>
        <inertial>
          <mass>1</mass>
          <inertia>
            <ixx>0.1</ixx>
            <ixy>0</ixy>
            <ixz>0</ixz>
            <iyy>0.1</iyy>
            <iyz>0</iyz>
            <izz>0.1</izz>
          </inertia>
          <pose frame=''>0 0 0 0 -0 0</pose>
        </inertial>
        <self_collide>0</self_collide>
        <enable_wind>0</enable_wind>
        <kinematic>0</kinematic>
        <pose frame=''>0 0 0 0 -0 0</pose>
        <gravity>0</gravity>
        <visual name='visual'>
          <geometry>
            <sphere>
              <radius>0.025</radius>
            </sphere>
          </geometry>
          <material>
            <script>
              <name>Gazebo/Green</name>
              <uri>file://media/materials/scripts/gazebo.material</uri>
            </script>
            <shader type='vertex'>
              <normal_map>__default__</normal_map>
            </shader>
            <ambient>0 1 0 1</ambient>
            <diffuse>0 1 0 1</diffuse>
            <specular>0 1 0 1</specular>
            <emissive>0 1 0 1</emissive>
          </material>
          <pose frame=''>0 0 0 0 -0 0</pose>
          <transparency>0</transparency>
          <cast_shadows>1</cast_shadows>
        </visual>
      </link>
      <static>0</static>
      <allow_auto_disable>1</allow_auto_disable>
      <plugin name='goalgazebo_plugin' filename='libgoalgazebo_plugin.so'/>
      <pose frame=''>1.26268 0.764758 0 0 -0 0</pose>
    </model>
    <state world_name='default'>
      <sim_time>13 236000000</sim_time>
      <real_time>13 307146538</real_time>
      <wall_time>1596973931 88567997</wall_time>
      <iterations>13236</iterations>
      <model name='goal'>
        <pose frame=''>1.26268 0.764758 0 0 -0 0</pose>
        <scale>1 1 1</scale>
        <link name='link'>
          <pose frame=''>1.26268 0.764758 0 0 -0 0</pose>
          <velocity>0 0 0 0 -0 0</velocity>
          <acceleration>0 0 0 0 -0 0</acceleration>
          <wrench>0 0 0 0 -0 0</wrench>
        </link>
      </model>
      <model name='ground_plane'>
        <pose frame=''>0 0 0 0 -0 0</pose>
        <scale>1 1 1</scale>
        <link name='link'>
          <pose frame=''>0 0 0 0 -0 0</pose>
          <velocity>0 0 0 0 -0 0</velocity>
          <acceleration>0 0 0 0 -0 0</acceleration>
          <wrench>0 0 0 0 -0 0</wrench>
        </link>
      </model>
      <model name='kuka_kr6r900sixx'>
        <pose frame=''>0 -0 -0 -0 -0 -0</pose>
        <scale>1 1 1</scale>
        <link name='link_1'>
          <pose frame=''>0.2 0 0.8 0 -1e-06 -1e-06</pose>
          <velocity>-0 1e-06 -0 -1e-06 -0 0</velocity>
          <acceleration>-0.000328 0.000701 -0.000294 -0.001388 -0.000643 0.000148</acceleration>
          <wrench>-0.004097 0.008757 -0.003675 0 -0 0</wrench>
        </link>
        <link name='link_2'>
          <pose frame=''>0.225 -0 0.8 0 -1.57 0</pose>
          <velocity>-0 1e-06 -0 -1e-06 0.000817 -0</velocity>
          <acceleration>-0.000328 0.000705 -0.00028 -0.000203 -0.000324 0.000198</acceleration>
          <wrench>-0.001639 0.003525 -0.001399 0 -0 0</wrench>
        </link>
        <link name='link_3'>
          <pose frame=''>0.225362 -0 1.255 0 -2e-06 -1e-06</pose>
          <velocity>0.000372 1e-06 -0 -1e-06 -0.000329 0</velocity>
          <acceleration>-0.000398 0.001043 -0.000282 -0.000797 -0.000146 8.6e-05</acceleration>
          <wrench>-0.001988 0.005216 -0.001408 0 -0 0</wrench>
        </link>
        <link name='link_4'>
          <pose frame=''>0.225362 -0 1.29 -1.3e-05 2e-05 -1e-06</pose>
          <velocity>0.00036 1e-06 -0 0 -0.000329 -1e-06</velocity>
          <acceleration>-0.000378 0.001036 -0.000282 -0.000416 -0.000131 -0.000792</acceleration>
          <wrench>-0.001892 0.005179 -0.001412 0 -0 0</wrench>
        </link>
        <link name='link_5'>
          <pose frame=''>0.645362 -0 1.28999 -0.016498 1.57002 -0.016499</pose>
          <velocity>0.00036 0 0.000138 -0 0.001394 -2e-06</velocity>
          <acceleration>-0.000367 0.000574 -0.000215 -0.000166 -0.000142 -0.001179</acceleration>
          <wrench>-0.000733 0.001148 -0.000431 0 -0 0</wrench>
        </link>
        <link name='link_6'>
          <pose frame=''>0.645424 -1e-06 1.20999 -0.016559 1.57003 -0.016558</pose>
          <velocity>0.000249 0 0.000138 -2e-06 0.001393 -3e-06</velocity>
          <acceleration>-0.000321 0.000429 -0.000213 -0.001425 -0.000425 -0.001296</acceleration>
          <wrench>-0.000706 0.000944 -0.000469 0 -0 0</wrench>
        </link>
        <link name='table'>
          <pose frame=''>0.6 0 0.2 -0 -0 -0</pose>
          <velocity>-0 0 -0 -1e-06 -0 -0</velocity>
          <acceleration>-9.1e-05 9.2e-05 -0.000131 -0.000624 -0.000401 -5.5e-05</acceleration>
          <wrench>-0.011832 0.01194 -0.017094 0 -0 0</wrench>
        </link>
      </model>
      <model name='unit_box'>
        <pose frame=''>1.08452 0.735173 0.020001 -1.6e-05 -5.3e-05 -5e-06</pose>
        <scale>1 1 1</scale>
        <link name='link'>
          <pose frame=''>1.08452 0.735173 0.020001 -1.6e-05 -5.3e-05 -5e-06</pose>
          <velocity>0 0 0 0 -0 0</velocity>
          <acceleration>0.028505 -0.028524 2.10749 1.42545 1.42544 2e-06</acceleration>
          <wrench>0.028505 -0.028524 2.10749 0 -0 0</wrench>
        </link>
      </model>
      <light name='sun'>
        <pose frame=''>0 0 10 0 -0 0</pose>
      </light>
    </state>
  </world>
</sdf>
